<?xml version="1.0"?>
<robot xmlns:xacro="http://www.ros.org/wiki/xacro" name="example">

  <xacro:include filename="gazebo.xacro"/>
  <link name="world"></link>

  <joint name="base_joint" type="fixed">
      <origin xyz="0 0 0" rpy="0 0 0"/>
      <parent link="world"/>
      <child link="link_0"/>        
  </joint>

  <link name="link_0">
    <visual>
      <geometry>
        <mesh filename="file:///$(find dummy_description)/meshes/link_0.stl"/>
      </geometry>
    </visual>

    <collision>
      <geometry>
        <mesh filename="file:///$(find dummy_description)/meshes/link_0.stl"/>
      </geometry>
    </collision>

    <xacro:inertial_box mass="10.5" x="0.3" y="0.3" z="0.15">
        <origin xyz="0.15 0 0.075" rpy="0 0 0"/>
    </xacro:inertial_box>
  </link>

  <link name="link_1">
    <visual>
      <geometry>
        <mesh filename="file:///$(find dummy_description)/meshes/link_1.stl"/>
      </geometry>
    </visual>
    <collision>
      <geometry>
        <mesh filename="file:///$(find dummy_description)/meshes/link_1.stl"/>
      </geometry>
    </collision>
    <xacro:inertial_box mass="10.5" x="0.3" y="0.3" z="0.15">
        <origin xyz="0.15 0 0.075" rpy="0 0 0"/>
    </xacro:inertial_box>
  </link>

  <joint name="joint_1" type="revolute">
    <parent link="link_0"/>
    <child link="link_1"/>
    <origin xyz="0 0 0.2" rpy="0 0 0"/> 
    <axis xyz="0 0 1"/>
    <limit 
      lower="-3.1459" 
      upper="3.1459" 
      velocity="1000.0" 
      effort="1000.0"/>
  </joint>

  <link name="link_2">
    <visual>
      <origin xyz="0.0 0.0 0.0" rpy="0 0 ${-3.14/2}"/> 
      <geometry>
        <mesh filename="file:///$(find dummy_description)/meshes/link_2.stl"/>
      </geometry>
    </visual>
    <collision>
      <origin xyz="0.0 0.0 0.0" rpy="0 0 ${-3.14/2}"/> 
      <geometry>
        <mesh filename="file:///$(find dummy_description)/meshes/link_2.stl"/>
      </geometry>
    </collision>
    <xacro:inertial_box mass="10.5" x="0.3" y="0.3" z="0.15">
        <origin xyz="0.15 0 0.075" rpy="0 0 0"/>
    </xacro:inertial_box>
  </link>
  
  <joint name="joint_2" type="revolute">
    <parent link="link_1"/>
    <child link="link_2"/>
    <origin xyz="0.0 -0.12 0.0" rpy="${-3.14/2} 0 0"/> 
    <axis xyz="0 0 1"/>
    <limit 
      lower="-3.1459" 
      upper="3.1459" 
      velocity="1000.0" 
      effort="1000.0"/>
  </joint>

  <link name="link_3">
    <visual>
      <origin xyz="0.0 0.0 0.0" rpy="0 0 ${-3.14/2}"/> 
      <geometry>
        <mesh filename="file:///$(find dummy_description)/meshes/link_3.stl"/>
      </geometry>
    </visual>
    <collision>
      <origin xyz="0.0 0.0 0.0" rpy="0 0 ${-3.14/2}"/> 
      <geometry>
        <mesh filename="file:///$(find dummy_description)/meshes/link_3.stl"/>
      </geometry>
    </collision>
    <xacro:inertial_box mass="10.5" x="0.3" y="0.3" z="0.15">
        <origin xyz="0.15 0 0.075" rpy="0 0 0"/>
    </xacro:inertial_box>
  </link>
  
  <joint name="joint_3" type="revolute">
    <parent link="link_2"/>
    <child link="link_3"/>
    <origin xyz="0.0 -0.25 0.1" rpy="0 0 0"/> 
    <axis xyz="0 0 1"/>
    <limit 
      lower="-3.1459" 
      upper="3.1459" 
      velocity="1000.0" 
      effort="1000.0"/>
  </joint>

  <link name="end_effector">
    <visual>
      <origin xyz="0.0 0.0 0.0" rpy="0 0 0"/> 
      <geometry>
        <mesh filename="file:///$(find dummy_description)/meshes/end_effector.stl"/>
      </geometry>
    </visual>
    <collision>
      <origin xyz="0.0 0.0 0.0" rpy="0 0 ${-3.14/2}"/> 
      <geometry>
        <mesh filename="file:///$(find dummy_description)/meshes/end_effector.stl"/>
      </geometry>
    </collision>
    <xacro:inertial_box mass="10.5" x="0.3" y="0.3" z="0.15">
        <origin xyz="0.15 0 0.075" rpy="0 0 0"/>
    </xacro:inertial_box>
  </link>
  
  <joint name="joint_end_effector" type="fixed">
    <parent link="link_3"/>
    <child link="end_effector"/>
    <origin xyz="0.0 -0.28 0.0" rpy="${3.14/2} 0 0"/> 
  </joint>

</robot>